0.txt Graph execution error:

Detected at node 'sequential/conv2d/Relu' defined at (most recent call last):
    File "C:\Users\kwarkmc\.conda\envs\capstone\lib\runpy.py", line 196, in _run_module_as_main
      return _run_code(code, main_globals, None,
    File "C:\Users\kwarkmc\.conda\envs\capstone\lib\runpy.py", line 86, in _run_code
      exec(code, run_globals)
    File "C:\Users\kwarkmc\.conda\envs\capstone\lib\site-packages\ipykernel_launcher.py", line 17, in <module>
      app.launch_new_instance()
    File "C:\Users\kwarkmc\.conda\envs\capstone\lib\site-packages\traitlets\config\application.py", line 846, in launch_instance
      app.start()
    File "C:\Users\kwarkmc\.conda\envs\capstone\lib\site-packages\ipykernel\kernelapp.py", line 712, in start
      self.io_loop.start()
    File "C:\Users\kwarkmc\.conda\envs\capstone\lib\site-packages\tornado\platform\asyncio.py", line 215, in start
      self.asyncio_loop.run_forever()
    File "C:\Users\kwarkmc\.conda\envs\capstone\lib\asyncio\base_events.py", line 603, in run_forever
      self._run_once()
    File "C:\Users\kwarkmc\.conda\envs\capstone\lib\asyncio\base_events.py", line 1899, in _run_once
      handle._run()
    File "C:\Users\kwarkmc\.conda\envs\capstone\lib\asyncio\events.py", line 80, in _run
      self._context.run(self._callback, *self._args)
    File "C:\Users\kwarkmc\.conda\envs\capstone\lib\site-packages\ipykernel\kernelbase.py", line 510, in dispatch_queue
      await self.process_one()
    File "C:\Users\kwarkmc\.conda\envs\capstone\lib\site-packages\ipykernel\kernelbase.py", line 499, in process_one
      await dispatch(*args)
    File "C:\Users\kwarkmc\.conda\envs\capstone\lib\site-packages\ipykernel\kernelbase.py", line 406, in dispatch_shell
      await result
    File "C:\Users\kwarkmc\.conda\envs\capstone\lib\site-packages\ipykernel\kernelbase.py", line 730, in execute_request
      reply_content = await reply_content
    File "C:\Users\kwarkmc\.conda\envs\capstone\lib\site-packages\ipykernel\ipkernel.py", line 383, in do_execute
      res = shell.run_cell(
    File "C:\Users\kwarkmc\.conda\envs\capstone\lib\site-packages\ipykernel\zmqshell.py", line 528, in run_cell
      return super().run_cell(*args, **kwargs)
    File "C:\Users\kwarkmc\.conda\envs\capstone\lib\site-packages\IPython\core\interactiveshell.py", line 2940, in run_cell
      result = self._run_cell(
    File "C:\Users\kwarkmc\.conda\envs\capstone\lib\site-packages\IPython\core\interactiveshell.py", line 2995, in _run_cell
      return runner(coro)
    File "C:\Users\kwarkmc\.conda\envs\capstone\lib\site-packages\IPython\core\async_helpers.py", line 129, in _pseudo_sync_runner
      coro.send(None)
    File "C:\Users\kwarkmc\.conda\envs\capstone\lib\site-packages\IPython\core\interactiveshell.py", line 3194, in run_cell_async
      has_raised = await self.run_ast_nodes(code_ast.body, cell_name,
    File "C:\Users\kwarkmc\.conda\envs\capstone\lib\site-packages\IPython\core\interactiveshell.py", line 3373, in run_ast_nodes
      if await self.run_code(code, result, async_=asy):
    File "C:\Users\kwarkmc\.conda\envs\capstone\lib\site-packages\IPython\core\interactiveshell.py", line 3433, in run_code
      exec(code_obj, self.user_global_ns, self.user_ns)
    File "C:\Users\kwarkmc\AppData\Local\Temp\ipykernel_9908\1647805615.py", line 6, in <module>
      TTE_Result = predict_pos_neg("input 입력할것")
    File "C:\Users\kwarkmc\AppData\Local\Temp\ipykernel_9908\3875805020.py", line 6, in predict_pos_neg
      score = float(model.predict(data))
    File "C:\Users\kwarkmc\.conda\envs\capstone\lib\site-packages\keras\utils\traceback_utils.py", line 65, in error_handler
      return fn(*args, **kwargs)
    File "C:\Users\kwarkmc\.conda\envs\capstone\lib\site-packages\keras\engine\training.py", line 2350, in predict
      tmp_batch_outputs = self.predict_function(iterator)
    File "C:\Users\kwarkmc\.conda\envs\capstone\lib\site-packages\keras\engine\training.py", line 2137, in predict_function
      return step_function(self, iterator)
    File "C:\Users\kwarkmc\.conda\envs\capstone\lib\site-packages\keras\engine\training.py", line 2123, in step_function
      outputs = model.distribute_strategy.run(run_step, args=(data,))
    File "C:\Users\kwarkmc\.conda\envs\capstone\lib\site-packages\keras\engine\training.py", line 2111, in run_step
      outputs = model.predict_step(data)
    File "C:\Users\kwarkmc\.conda\envs\capstone\lib\site-packages\keras\engine\training.py", line 2079, in predict_step
      return self(x, training=False)
    File "C:\Users\kwarkmc\.conda\envs\capstone\lib\site-packages\keras\utils\traceback_utils.py", line 65, in error_handler
      return fn(*args, **kwargs)
    File "C:\Users\kwarkmc\.conda\envs\capstone\lib\site-packages\keras\engine\training.py", line 561, in __call__
      return super().__call__(*args, **kwargs)
    File "C:\Users\kwarkmc\.conda\envs\capstone\lib\site-packages\keras\utils\traceback_utils.py", line 65, in error_handler
      return fn(*args, **kwargs)
    File "C:\Users\kwarkmc\.conda\envs\capstone\lib\site-packages\keras\engine\base_layer.py", line 1132, in __call__
      outputs = call_fn(inputs, *args, **kwargs)
    File "C:\Users\kwarkmc\.conda\envs\capstone\lib\site-packages\keras\utils\traceback_utils.py", line 96, in error_handler
      return fn(*args, **kwargs)
    File "C:\Users\kwarkmc\.conda\envs\capstone\lib\site-packages\keras\engine\sequential.py", line 413, in call
      return super().call(inputs, training=training, mask=mask)
    File "C:\Users\kwarkmc\.conda\envs\capstone\lib\site-packages\keras\engine\functional.py", line 511, in call
      return self._run_internal_graph(inputs, training=training, mask=mask)
    File "C:\Users\kwarkmc\.conda\envs\capstone\lib\site-packages\keras\engine\functional.py", line 668, in _run_internal_graph
      outputs = node.layer(*args, **kwargs)
    File "C:\Users\kwarkmc\.conda\envs\capstone\lib\site-packages\keras\utils\traceback_utils.py", line 65, in error_handler
      return fn(*args, **kwargs)
    File "C:\Users\kwarkmc\.conda\envs\capstone\lib\site-packages\keras\engine\base_layer.py", line 1132, in __call__
      outputs = call_fn(inputs, *args, **kwargs)
    File "C:\Users\kwarkmc\.conda\envs\capstone\lib\site-packages\keras\utils\traceback_utils.py", line 96, in error_handler
      return fn(*args, **kwargs)
    File "C:\Users\kwarkmc\.conda\envs\capstone\lib\site-packages\keras\layers\convolutional\base_conv.py", line 314, in call
      return self.activation(outputs)
    File "C:\Users\kwarkmc\.conda\envs\capstone\lib\site-packages\keras\activations.py", line 317, in relu
      return backend.relu(
    File "C:\Users\kwarkmc\.conda\envs\capstone\lib\site-packages\keras\backend.py", line 5369, in relu
      x = tf.nn.relu(x)
Node: 'sequential/conv2d/Relu'
convolution input must be 4-dimensional: [1,20000]
	 [[{{node sequential/conv2d/Relu}}]] [Op:__inference_predict_function_458]
